{"uuid": "84a8a494-9dd3-416f-b52f-64103b7955ef", "children": ["6c11caab-5144-4f7f-ae7d-cdfceb583f78"], "befores": [{"name": "mobile_management", "status": "broken", "statusDetails": {"message": "selenium.common.exceptions.WebDriverException: Message: An unknown server-side error occurred while processing the command. Original error: Error executing adbExec. Original error: 'Command '/home/ivank/Android/Sdk/platform-tools/adb -P 5037 -s emulator-5554 install -r /home/ivank/.appium/node_modules/appium-uiautomator2-driver/node_modules/appium-uiautomator2-server/apks/appium-uiautomator2-server-v5.12.16.apk' timed out after 20000ms'. Try to increase the 20000ms adb execution timeout represented by 'uiautomator2ServerInstallTimeout' capability\nStacktrace:\nUnknownError: An unknown server-side error occurred while processing the command. Original error: Error executing adbExec. Original error: 'Command '/home/ivank/Android/Sdk/platform-tools/adb -P 5037 -s emulator-5554 install -r /home/ivank/.appium/node_modules/appium-uiautomator2-driver/node_modules/appium-uiautomator2-server/apks/appium-uiautomator2-server-v5.12.16.apk' timed out after 20000ms'. Try to increase the 20000ms adb execution timeout represented by 'uiautomator2ServerInstallTimeout' capability\n    at getResponseForW3CError (/usr/lib/node_modules/appium/node_modules/@appium/base-driver/lib/protocol/errors.js:1092:9)\n    at asyncHandler (/usr/lib/node_modules/appium/node_modules/@appium/base-driver/lib/protocol/protocol.js:491:57)\n", "trace": "  File \"/home/ivank/.cache/pypoetry/virtualenvs/qa-guru-7-21-irDqIFHX-py3.11/lib/python3.11/site-packages/pluggy/_callers.py\", line 77, in _multicall\n    res = hook_impl.function(*args)\n          ^^^^^^^^^^^^^^^^^^^^^^^^^\n  File \"/home/ivank/.cache/pypoetry/virtualenvs/qa-guru-7-21-irDqIFHX-py3.11/lib/python3.11/site-packages/_pytest/fixtures.py\", line 1123, in pytest_fixture_setup\n    result = call_fixture_func(fixturefunc, request, kwargs)\n             ^^^^^^^^^^^^^^^^^^^^^^^^^^^^^^^^^^^^^^^^^^^^^^^\n  File \"/home/ivank/.cache/pypoetry/virtualenvs/qa-guru-7-21-irDqIFHX-py3.11/lib/python3.11/site-packages/_pytest/fixtures.py\", line 895, in call_fixture_func\n    fixture_result = next(generator)\n                     ^^^^^^^^^^^^^^^\n  File \"/home/ivank/learn/qaguru/qa_guru_7_21/tests/mobile/conftest.py\", line 17, in mobile_management\n    browser.config.driver = webdriver.Remote(\n                            ^^^^^^^^^^^^^^^^^\n  File \"/home/ivank/.cache/pypoetry/virtualenvs/qa-guru-7-21-irDqIFHX-py3.11/lib/python3.11/site-packages/appium/webdriver/webdriver.py\", line 229, in __init__\n    super().__init__(\n  File \"/home/ivank/.cache/pypoetry/virtualenvs/qa-guru-7-21-irDqIFHX-py3.11/lib/python3.11/site-packages/selenium/webdriver/remote/webdriver.py\", line 208, in __init__\n    self.start_session(capabilities)\n  File \"/home/ivank/.cache/pypoetry/virtualenvs/qa-guru-7-21-irDqIFHX-py3.11/lib/python3.11/site-packages/appium/webdriver/webdriver.py\", line 318, in start_session\n    response = self.execute(RemoteCommand.NEW_SESSION, w3c_caps)\n               ^^^^^^^^^^^^^^^^^^^^^^^^^^^^^^^^^^^^^^^^^^^^^^^^^\n  File \"/home/ivank/.cache/pypoetry/virtualenvs/qa-guru-7-21-irDqIFHX-py3.11/lib/python3.11/site-packages/selenium/webdriver/remote/webdriver.py\", line 347, in execute\n    self.error_handler.check_response(response)\n  File \"/home/ivank/.cache/pypoetry/virtualenvs/qa-guru-7-21-irDqIFHX-py3.11/lib/python3.11/site-packages/selenium/webdriver/remote/errorhandler.py\", line 229, in check_response\n    raise exception_class(message, screen, stacktrace)\n"}, "steps": [{"name": "Init app session", "status": "broken", "statusDetails": {"message": "selenium.common.exceptions.WebDriverException: Message: An unknown server-side error occurred while processing the command. Original error: Error executing adbExec. Original error: 'Command '/home/ivank/Android/Sdk/platform-tools/adb -P 5037 -s emulator-5554 install -r /home/ivank/.appium/node_modules/appium-uiautomator2-driver/node_modules/appium-uiautomator2-server/apks/appium-uiautomator2-server-v5.12.16.apk' timed out after 20000ms'. Try to increase the 20000ms adb execution timeout represented by 'uiautomator2ServerInstallTimeout' capability\nStacktrace:\nUnknownError: An unknown server-side error occurred while processing the command. Original error: Error executing adbExec. Original error: 'Command '/home/ivank/Android/Sdk/platform-tools/adb -P 5037 -s emulator-5554 install -r /home/ivank/.appium/node_modules/appium-uiautomator2-driver/node_modules/appium-uiautomator2-server/apks/appium-uiautomator2-server-v5.12.16.apk' timed out after 20000ms'. Try to increase the 20000ms adb execution timeout represented by 'uiautomator2ServerInstallTimeout' capability\n    at getResponseForW3CError (/usr/lib/node_modules/appium/node_modules/@appium/base-driver/lib/protocol/errors.js:1092:9)\n    at asyncHandler (/usr/lib/node_modules/appium/node_modules/@appium/base-driver/lib/protocol/protocol.js:491:57)\n", "trace": "  File \"/home/ivank/learn/qaguru/qa_guru_7_21/tests/mobile/conftest.py\", line 17, in mobile_management\n    browser.config.driver = webdriver.Remote(\n                            ^^^^^^^^^^^^^^^^^\n  File \"/home/ivank/.cache/pypoetry/virtualenvs/qa-guru-7-21-irDqIFHX-py3.11/lib/python3.11/site-packages/appium/webdriver/webdriver.py\", line 229, in __init__\n    super().__init__(\n  File \"/home/ivank/.cache/pypoetry/virtualenvs/qa-guru-7-21-irDqIFHX-py3.11/lib/python3.11/site-packages/selenium/webdriver/remote/webdriver.py\", line 208, in __init__\n    self.start_session(capabilities)\n  File \"/home/ivank/.cache/pypoetry/virtualenvs/qa-guru-7-21-irDqIFHX-py3.11/lib/python3.11/site-packages/appium/webdriver/webdriver.py\", line 318, in start_session\n    response = self.execute(RemoteCommand.NEW_SESSION, w3c_caps)\n               ^^^^^^^^^^^^^^^^^^^^^^^^^^^^^^^^^^^^^^^^^^^^^^^^^\n  File \"/home/ivank/.cache/pypoetry/virtualenvs/qa-guru-7-21-irDqIFHX-py3.11/lib/python3.11/site-packages/selenium/webdriver/remote/webdriver.py\", line 347, in execute\n    self.error_handler.check_response(response)\n  File \"/home/ivank/.cache/pypoetry/virtualenvs/qa-guru-7-21-irDqIFHX-py3.11/lib/python3.11/site-packages/selenium/webdriver/remote/errorhandler.py\", line 229, in check_response\n    raise exception_class(message, screen, stacktrace)\n"}, "start": 1700042234034, "stop": 1700042306704}], "start": 1700042234034, "stop": 1700042306709}], "start": 1700042234034, "stop": 1700042306862}